<?xml version="1.0"?>
<robot name="my_robot">

    <!-- Base Link -->
    <link name="base_link">
        <inertial>
            <origin xyz="0 0 0" />
            <mass value="1.0" />
            <inertia ixx="0.1" ixy="0.0" ixz="0.0" iyy="0.1" iyz="0.0" izz="0.1" />
        </inertial>
        <visual>
            <origin xyz="0 0 0" rpy="0 0 0" />
            <geometry>
                <box size="0.5 0.5 0.2" />
            </geometry>
            <material name="white">
                <color rgba="1 1 1 1" />
            </material>
        </visual>
        <collision>
            <origin xyz="0 0 0" rpy="0 0 0" />
            <geometry>
                <box size="0.5 0.5 0.2" />
            </geometry>
        </collision>
    </link>

    <!-- Left Wheel -->
    <link name="left_wheel">
        <visual>
            <geometry>
                <cylinder length="0.05" radius="0.1" />
            </geometry>
            <material name="black">
                <color rgba="0 0 0 1" />
            </material>
        </visual>
        <collision>
            <geometry>
                <cylinder length="0.05" radius="0.1" />
            </geometry>
        </collision>
    </link>

    <!-- Right Wheel -->
    <link name="right_wheel">
        <visual>
            <geometry>
                <cylinder length="0.05" radius="0.1" />
            </geometry>
            <material name="black">
                <color rgba="0 0 0 1" />
            </material>
        </visual>
        <collision>
            <geometry>
                <cylinder length="0.05" radius="0.1" />
            </geometry>
        </collision>
    </link>

    <!-- Joints -->
    <joint name="left_wheel_joint" type="continuous">
        <parent link="base_link" />
        <child link="left_wheel" />
        <origin xyz="-0.25 0.3 0" rpy="0 0 0" />
        <axis xyz="0 1 0" />
        <limit effort="10.0" velocity="10.0" />
    </joint>

    <joint name="right_wheel_joint" type="continuous">
        <parent link="base_link" />
        <child link="right_wheel" />
        <origin xyz="-0.25 -0.3 0" rpy="0 0 0" />
        <axis xyz="0 1 0" />
        <limit effort="10.0" velocity="10.0" />
    </joint>

    <!-- Plugins -->
    <gazebo>
        <plugin name="gazebo_ros_diff_drive" filename="libgazebo_ros_diff_drive.so">
            <robotNamespace>diff_drive</robotNamespace>
            <left_wheel>left_wheel_joint</left_wheel>
            <right_wheel>right_wheel_joint</right_wheel>
            <wheel_separation>0.6</wheel_separation>
            <wheel_diameter>0.2</wheel_diameter>
            <commandTopic>cmd_vel</commandTopic>
            <odometryTopic>odom</odometryTopic>
            <odometryFrame>odom</odometryFrame>
            <robotBaseFrame>base_link</robotBaseFrame>
            <updateRate>100</updateRate>
        </plugin>
    </gazebo>
</robot>
